Workbook
Name Slicer_Category: #N/A
Name Slicer_Date: #N/A
Name Slicer_Discount: #N/A
Name Slicer_Order_ID: #N/A
Name Slicer_Product: #N/A
Name Slicer_Profit: #N/A
Name Slicer_Region: #N/A
Name Slicer_Sales: #N/A
Name Slicer_Segment: #N/A
Name Slicer_Sub_Category: #N/A

Sheet 01_Main_Dataset
A1: Order_ID | B1: Date | C1: Region | D1: Category | E1: Sub_Category | F1: Product | G1: Customer | H1: Segment | I1: Sales | J1: Quantity | K1: Profit | L1: Discount
A2: ORD00002 | B2: 45954 | C2: West | D2: Technology | E2: SubCat | F2: Product2 | G2: Cust2 | H2: Consumer | I2: 971.62 | J2: 5 | K2: 327.09 | L2: 0.1 | N2: Name:- Debkanta Nandi
A3: ORD00003 | B3: 45921 | C3: South | D3: Office Supplies | E3: SubCat | F3: Product3 | G3: Cust3 | H3: Consumer | I3: 182.55 | J3: 8 | K3: 44.65 | L3: 0.08 | N3: Course Name:- DPBA, Batch:-ANP-D3870
A4: ORD00004 | B4: 45675 | C4: West | D4: Technology | E4: SubCat | F4: Product4 | G4: Cust4 | H4: Consumer | I4: 298.11 | J4: 4 | K4: 109.47 | L4: 0.08 | N4: Subject:- Excel Report Project
A5: ORD00005 | B5: 45658 | C5: East | D5: Technology | E5: SubCat | F5: Product5 | G5: Cust5 | H5: Consumer | I5: 713.06 | J5: 1 | K5: 186.05 | L5: 0.1 | N5: Project Name:-Sales & Performance Analysis Dashboard
A6: ORD00006 | B6: 45722 | C6: East | D6: Furniture | E6: SubCat | F6: Product6 | G6: Cust6 | H6: Home Office | I6: 1037.92 | J6: 2 | K6: 393.31 | L6: 0.06
A7: ORD00007 | B7: 45975 | C7: East | D7: Technology | E7: SubCat | F7: Product7 | G7: Cust7 | H7: Corporate | I7: 652.03 | J7: 5 | K7: 260.8 | L7: 0.17
A8: ORD00008 | B8: 45692 | C8: North | D8: Furniture | E8: SubCat | F8: Product8 | G8: Cust8 | H8: Consumer | I8: 1260.49 | J8: 2 | K8: 365.39 | L8: 0.07
A9: ORD00009 | B9: 45708 | C9: East | D9: Technology | E9: SubCat | F9: Product9 | G9: Cust9 | H9: Home Office | I9: 1173.22 | J9: 8 | K9: 180.51 | L9: 0.21
A10: ORD00010 | B10: 46005 | C10: North | D10: Office Supplies | E10: SubCat | F10: Product10 | G10: Cust10 | H10: Consumer | I10: 312.23 | J10: 9 | K10: 102.62 | L10: 0.17
A11: ORD00011 | B11: 45778 | C11: East | D11: Furniture | E11: SubCat | F11: Product11 | G11: Cust11 | H11: Consumer | I11: 1797.94 | J11: 10 | K11: 632.53 | L11: 0.21
A12: ORD00012 | B12: 45976 | C12: North | D12: Technology | E12: SubCat | F12: Product12 | G12: Cust12 | H12: Home Office | I12: 1781.4 | J12: 1 | K12: 361.91 | L12: 0.18
A13: ORD00013 | B13: 45928 | C13: South | D13: Furniture | E13: SubCat | F13: Product13 | G13: Cust13 | H13: Home Office | I13: 1205.07 | J13: 9 | K13: 367.14 | L13: 0.1
A14: ORD00014 | B14: 45927 | C14: East | D14: Technology | E14: SubCat | F14: Product14 | G14: Cust14 | H14: Home Office | I14: 913.99 | J14: 1 | K14: 324.67 | L14: 0.12
A15: ORD00015 | B15: 45834 | C15: South | D15: Furniture | E15: SubCat | F15: Product15 | G15: Cust15 | H15: Home Office | I15: 738.88 | J15: 7 | K15: 95.17 | L15: 0.27
A16: ORD00016 | B16: 45986 | C16: East | D16: Office Supplies | E16: SubCat | F16: Product16 | G16: Cust16 | H16: Consumer | I16: 750.85 | J16: 5 | K16: 281.77 | L16: 0.12
A17: ORD00017 | B17: 45884 | C17: West | D17: Office Supplies | E17: SubCat | F17: Product17 | G17: Cust17 | H17: Home Office | I17: 1196.5 | J17: 2 | K17: 354.35 | L17: 0.25
... A401: ORD00401 | B401: 45727 | C401: East | D401: Office Supplies | E401: SubCat | F401: Product401 | G401: Cust401 | H401: Home Office | I401: 1638.6 | J401: 6 | K401: 600.12 | L401: 0.07

Sheet 02_Data_Cleaning
A1: Questions | B1: Order_ID | C1: Value1 | D1: Value2 | E1: Value3
A2: 1.Identify and remove duplicate Order_ID records | B2: ='01_Main_Dataset'!A2 -> ORD00002 | C2: =PROPER('01_Main_Dataset'!C2) -> West | D2: =TRIM('01_Main_Dataset'!F2) -> Product2 | E2: ='01_Main_Dataset'!B2 -> 45954
A3: 2.Detect and fill missing values in Sales column | B3: ='01_Main_Dataset'!A3 -> ORD00003 | C3: =PROPER('01_Main_Dataset'!C3) -> South | D3: =TRIM('01_Main_Dataset'!F3) -> Product3 | E3: ='01_Main_Dataset'!B3 -> 45921
A4: 3.Standardize Region names using proper case | B4: ='01_Main_Dataset'!A4 -> ORD00004 | C4: =PROPER('01_Main_Dataset'!C4) -> West | D4: =TRIM('01_Main_Dataset'!F4) -> Product4 | E4: ='01_Main_Dataset'!B4 -> 45675
A5: 4.Remove leading/trailing spaces from Product names | B5: ='01_Main_Dataset'!A5 -> ORD00005 | C5: =PROPER('01_Main_Dataset'!C5) -> East | D5: =TRIM('01_Main_Dataset'!F5) -> Product5 | E5: ='01_Main_Dataset'!B5 -> 45658
A6: 5.Validate date format consistency across dataset | B6: ='01_Main_Dataset'!A6 -> ORD00006 | C6: =PROPER('01_Main_Dataset'!C6) -> East | D6: =TRIM('01_Main_Dataset'!F6) -> Product6 | E6: ='01_Main_Dataset'!B6 -> 45722
B7: ='01_Main_Dataset'!A7 -> ORD00007 | C7: =PROPER('01_Main_Dataset'!C7) -> East | D7: =TRIM('01_Main_Dataset'!F7) -> Product7 | E7: ='01_Main_Dataset'!B7 -> 45975
B8: ='01_Main_Dataset'!A8 -> ORD00008 | C8: =PROPER('01_Main_Dataset'!C8) -> North | D8: =TRIM('01_Main_Dataset'!F8) -> Product8 | E8: ='01_Main_Dataset'!B8 -> 45692
B9: ='01_Main_Dataset'!A9 -> ORD00009 | C9: =PROPER('01_Main_Dataset'!C9) -> East | D9: =TRIM('01_Main_Dataset'!F9) -> Product9 | E9: ='01_Main_Dataset'!B9 -> 45708
B10: ='01_Main_Dataset'!A10 -> ORD00010 | C10: =PROPER('01_Main_Dataset'!C10) -> North | D10: =TRIM('01_Main_Dataset'!F10) -> Product10 | E10: ='01_Main_Dataset'!B10 -> 46005
B11: ='01_Main_Dataset'!A11 -> ORD00011 | C11: =PROPER('01_Main_Dataset'!C11) -> East | D11: =TRIM('01_Main_Dataset'!F11) -> Product11 | E11: ='01_Main_Dataset'!B11 -> 45778
B12: ='01_Main_Dataset'!A12 -> ORD00012 | C12: =PROPER('01_Main_Dataset'!C12) -> North | D12: =TRIM('01_Main_Dataset'!F12) -> Product12 | E12: ='01_Main_Dataset'!B12 -> 45976
B13: ='01_Main_Dataset'!A13 -> ORD00013 | C13: =PROPER('01_Main_Dataset'!C13) -> South | D13: =TRIM('01_Main_Dataset'!F13) -> Product13 | E13: ='01_Main_Dataset'!B13 -> 45928
B14: ='01_Main_Dataset'!A14 -> ORD00014 | C14: =PROPER('01_Main_Dataset'!C14) -> East | D14: =TRIM('01_Main_Dataset'!F14) -> Product14 | E14: ='01_Main_Dataset'!B14 -> 45927
B15: ='01_Main_Dataset'!A15 -> ORD00015 | C15: =PROPER('01_Main_Dataset'!C15) -> South | D15: =TRIM('01_Main_Dataset'!F15) -> Product15 | E15: ='01_Main_Dataset'!B15 -> 45834
B16: ='01_Main_Dataset'!A16 -> ORD00016 | C16: =PROPER('01_Main_Dataset'!C16) -> East | D16: =TRIM('01_Main_Dataset'!F16) -> Product16 | E16: ='01_Main_Dataset'!B16 -> 45986
B17: ='01_Main_Dataset'!A17 -> ORD00017 | C17: =PROPER('01_Main_Dataset'!C17) -> West | D17: =TRIM('01_Main_Dataset'!F17) -> Product17 | E17: ='01_Main_Dataset'!B17 -> 45884
B18: ='01_Main_Dataset'!A18 -> ORD00018 | C18: =PROPER('01_Main_Dataset'!C18) -> East | D18: =TRIM('01_Main_Dataset'!F18) -> Product18 | E18: ='01_Main_Dataset'!B18 -> 45771
... B79: ='01_Main_Dataset'!A79 -> ORD00079 | C79: =PROPER('01_Main_Dataset'!C79) -> South | D79: =TRIM('01_Main_Dataset'!F79) -> Product79 | E79: ='01_Main_Dataset'!B79 -> 46011

Sheet 03_Cell_Referencing
A1: Questions | B1: Order_ID | C1: Value1 | D1: Value2 | E1: Value3
A2: 1.Extract year from Date column | B2: ='01_Main_Dataset'!A2 -> ORD00002 | C2: =YEAR('01_Main_Dataset'!B2) -> 2025 | D2: =TEXT('01_Main_Dataset'!B2,"MMM") -> Oct | E2: ='01_Main_Dataset'!I2*'01_Main_Dataset'!J2 -> 4858.1
A3: 2.Extract month name from Date column | B3: ='01_Main_Dataset'!A3 -> ORD00003 | C3: =YEAR('01_Main_Dataset'!B3) -> 2025 | D3: =TEXT('01_Main_Dataset'!B3,"MMM") -> Sep | E3: ='01_Main_Dataset'!I3*'01_Main_Dataset'!J3 -> 1460.4
A4: 3.Calculate Total Revenue (Sales * Quantity) | B4: ='01_Main_Dataset'!A4 -> ORD00004 | C4: =YEAR('01_Main_Dataset'!B4) -> 2025 | D4: =TEXT('01_Main_Dataset'!B4,"MMM") -> Jan | E4: ='01_Main_Dataset'!I4*'01_Main_Dataset'!J4 -> 1192.44
A5: 4.Demonstrate relative referencing in calculation | B5: ='01_Main_Dataset'!A5 -> ORD00005 | C5: =YEAR('01_Main_Dataset'!B5) -> 2025 | D5: =TEXT('01_Main_Dataset'!B5,"MMM") -> Jan | E5: ='01_Main_Dataset'!I5*'01_Main_Dataset'!J5 -> 713.06
A6: 5.Apply absolute reference for fixed value calculation | B6: ='01_Main_Dataset'!A6 -> ORD00006 | C6: =YEAR('01_Main_Dataset'!B6) -> 2025 | D6: =TEXT('01_Main_Dataset'!B6,"MMM") -> Mar | E6: ='01_Main_Dataset'!I6*'01_Main_Dataset'!J6 -> 2075.84
B7: ='01_Main_Dataset'!A7 -> ORD00007 | C7: =YEAR('01_Main_Dataset'!B7) -> 2025 | D7: =TEXT('01_Main_Dataset'!B7,"MMM") -> Nov | E7: ='01_Main_Dataset'!I7*'01_Main_Dataset'!J7 -> 3260.15
B8: ='01_Main_Dataset'!A8 -> ORD00008 | C8: =YEAR('01_Main_Dataset'!B8) -> 2025 | D8: =TEXT('01_Main_Dataset'!B8,"MMM") -> Feb | E8: ='01_Main_Dataset'!I8*'01_Main_Dataset'!J8 -> 2520.98
B9: ='01_Main_Dataset'!A9 -> ORD00009 | C9: =YEAR('01_Main_Dataset'!B9) -> 2025 | D9: =TEXT('01_Main_Dataset'!B9,"MMM") -> Feb | E9: ='01_Main_Dataset'!I9*'01_Main_Dataset'!J9 -> 9385.76
B10: ='01_Main_Dataset'!A10 -> ORD00010 | C10: =YEAR('01_Main_Dataset'!B10) -> 2025 | D10: =TEXT('01_Main_Dataset'!B10,"MMM") -> Dec | E10: ='01_Main_Dataset'!I10*'01_Main_Dataset'!J10 -> 2810.07
B11: ='01_Main_Dataset'!A11 -> ORD00011 | C11: =YEAR('01_Main_Dataset'!B11) -> 2025 | D11: =TEXT('01_Main_Dataset'!B11,"MMM") -> May | E11: ='01_Main_Dataset'!I11*'01_Main_Dataset'!J11 -> 17979.4
B12: ='01_Main_Dataset'!A12 -> ORD00012 | C12: =YEAR('01_Main_Dataset'!B12) -> 2025 | D12: =TEXT('01_Main_Dataset'!B12,"MMM") -> Nov | E12: ='01_Main_Dataset'!I12*'01_Main_Dataset'!J12 -> 1781.4
B13: ='01_Main_Dataset'!A13 -> ORD00013 | C13: =YEAR('01_Main_Dataset'!B13) -> 2025 | D13: =TEXT('01_Main_Dataset'!B13,"MMM") -> Sep | E13: ='01_Main_Dataset'!I13*'01_Main_Dataset'!J13 -> 10845.63
B14: ='01_Main_Dataset'!A14 -> ORD00014 | C14: =YEAR('01_Main_Dataset'!B14) -> 2025 | D14: =TEXT('01_Main_Dataset'!B14,"MMM") -> Sep | E14: ='01_Main_Dataset'!I14*'01_Main_Dataset'!J14 -> 913.99
B15: ='01_Main_Dataset'!A15 -> ORD00015 | C15: =YEAR('01_Main_Dataset'!B15) -> 2025 | D15: =TEXT('01_Main_Dataset'!B15,"MMM") -> Jun | E15: ='01_Main_Dataset'!I15*'01_Main_Dataset'!J15 -> 5172.16
B16: ='01_Main_Dataset'!A16 -> ORD00016 | C16: =YEAR('01_Main_Dataset'!B16) -> 2025 | D16: =TEXT('01_Main_Dataset'!B16,"MMM") -> Nov | E16: ='01_Main_Dataset'!I16*'01_Main_Dataset'!J16 -> 3754.25
B17: ='01_Main_Dataset'!A17 -> ORD00017 | C17: =YEAR('01_Main_Dataset'!B17) -> 2025 | D17: =TEXT('01_Main_Dataset'!B17,"MMM") -> Aug | E17: ='01_Main_Dataset'!I17*'01_Main_Dataset'!J17 -> 2393
B18: ='01_Main_Dataset'!A18 -> ORD00018 | C18: =YEAR('01_Main_Dataset'!B18) -> 2025 | D18: =TEXT('01_Main_Dataset'!B18,"MMM") -> Apr | E18: ='01_Main_Dataset'!I18*'01_Main_Dataset'!J18 -> 2084.38
... B79: ='01_Main_Dataset'!A79 -> ORD00079 | C79: =YEAR('01_Main_Dataset'!B79) -> 2025 | D79: =TEXT('01_Main_Dataset'!B79,"MMM") -> Dec | E79: ='01_Main_Dataset'!I79*'01_Main_Dataset'!J79 -> 8263.53

Sheet 04_Sorting_Filtering
A1: Question | C1: Order_ID | D1: Date | E1: Region | F1: Category | G1: Sub_Category | H1: Product | I1: Customer | J1: Segment | K1: Sales | L1: Quantity | M1: Profit | N1: Discount
A2: 1.Sort dataset by Sales in descending order | C2: ORD00054 | D2: 45726 | E2: South | F2: Technology | G2: SubCat | H2: Product54 | I2: Cust54 | J2: Consumer | K2: 1994.98 | L2: 7 | M2: 361.57 | N2: 0.06
A3: 2.Filter data for Technology category only | C3: ORD00302 | D3: 46010 | E3: North | F3: Technology | G3: SubCat | H3: Product302 | I3: Cust302 | J3: Corporate | K3: 1987.93 | L3: 8 | M3: 627.9 | N3: 0.03
A4: 3.Display top 10 orders by Profit | C4: ORD00228 | D4: 45720 | E4: East | F4: Furniture | G4: SubCat | H4: Product228 | I4: Cust228 | J4: Home Office | K4: 1977.2 | L4: 9 | M4: 459.31 | N4: 0.26
A5: 1.Sort dataset by Sales in descending order | C5: ORD00127 | D5: 45979 | E5: North | F5: Technology | G5: SubCat | H5: Product127 | I5: Cust127 | J5: Corporate | K5: 1975.53 | L5: 8 | M5: 376.33 | N5: 0.21
A6: 5.Sort by Region and then by Sales | C6: ORD00153 | D6: 45675 | E6: East | F6: Technology | G6: SubCat | H6: Product153 | I6: Cust153 | J6: Corporate | K6: 1973.56 | L6: 9 | M6: 622.36 | N6: 0.07
C7: ORD00219 | D7: 45759 | E7: South | F7: Furniture | G7: SubCat | H7: Product219 | I7: Cust219 | J7: Home Office | K7: 1972.02 | L7: 2 | M7: 106.07 | N7: 0.11
C8: ORD00055 | D8: 45933 | E8: South | F8: Furniture | G8: SubCat | H8: Product55 | I8: Cust55 | J8: Corporate | K8: 1970.76 | L8: 9 | M8: 683.91 | N8: 0.02
C9: ORD00280 | D9: 45794 | E9: East | F9: Office Supplies | G9: SubCat | H9: Product280 | I9: Cust280 | J9: Consumer | K9: 1968.45 | L9: 7 | M9: 672.5 | N9: 0.1
C10: ORD00370 | D10: 45788 | E10: North | F10: Furniture | G10: SubCat | H10: Product370 | I10: Cust370 | J10: Consumer | K10: 1954.83 | L10: 9 | M10: 717.68 | N10: 0.18
C11: ORD00104 | D11: 46019 | E11: West | F11: Office Supplies | G11: SubCat | H11: Product104 | I11: Cust104 | J11: Home Office | K11: 1951.97 | L11: 8 | M11: 242.52 | N11: 0.25
C12: ORD00358 | D12: 45758 | E12: West | F12: Furniture | G12: SubCat | H12: Product358 | I12: Cust358 | J12: Corporate | K12: 1951.69 | L12: 2 | M12: 333.71 | N12: 0.21
C13: ORD00045 | D13: 45947 | E13: South | F13: Office Supplies | G13: SubCat | H13: Product45 | I13: Cust45 | J13: Home Office | K13: 1948.51 | L13: 9 | M13: 186.79 | N13: 0.24
C14: ORD00090 | D14: 45888 | E14: West | F14: Office Supplies | G14: SubCat | H14: Product90 | I14: Cust90 | J14: Corporate | K14: 1937.62 | L14: 3 | M14: 589.79 | N14: 0.11
C15: ORD00327 | D15: 45729 | E15: West | F15: Office Supplies | G15: SubCat | H15: Product327 | I15: Cust327 | J15: Corporate | K15: 1926.43 | L15: 10 | M15: 582.45 | N15: 0.18
C16: ORD00174 | D16: 45972 | E16: West | F16: Office Supplies | G16: SubCat | H16: Product174 | I16: Cust174 | J16: Consumer | K16: 1914.54 | L16: 8 | M16: 192.01 | N16: 0.08
C17: ORD00218 | D17: 45939 | E17: East | F17: Office Supplies | G17: SubCat | H17: Product218 | I17: Cust218 | J17: Home Office | K17: 1911.63 | L17: 9 | M17: 645.24 | N17: 0.28
C18: ORD00124 | D18: 45809 | E18: West | F18: Technology | G18: SubCat | H18: Product124 | I18: Cust124 | J18: Consumer | K18: 1903.38 | L18: 1 | M18: 139.03 | N18: 0.14
... C20: ORD00066 | D20: 45801 | E20: North | F20: Office Supplies | G20: SubCat | H20: Product66 | I20: Cust66 | J20: Consumer | K20: 1893.28 | L20: 3 | M20: 620.61 | N20: 0.2
A21: 2.Sort dataset by category is only Technology | C21: ORD00035 | D21: 45881 | E21: South | F21: Technology | G21: SubCat | H21: Product35 | I21: Cust35 | J21: Home Office | K21: 1881.77 | L21: 3 | M21: 605.05 | N21: 0.25
C22: ORD00187 | D22: 45753 | E22: East | F22: Technology | G22: SubCat | H22: Product187 | I22: Cust187 | J22: Home Office | K22: 1881.53 | L22: 4 | M22: 711.79 | N22: 0.18
C23: ORD00380 | D23: 45926 | E23: West | F23: Office Supplies | G23: SubCat | H23: Product380 | I23: Cust380 | J23: Home Office | K23: 1879.41 | L23: 9 | M23: 666.22 | N23: 0.29
C24: ORD00068 | D24: 45936 | E24: West | F24: Technology | G24: SubCat | H24: Product68 | I24: Cust68 | J24: Consumer | K24: 1865.98 | L24: 3 | M24: 331.52 | N24: 0.02
C25: ORD00193 | D25: 45839 | E25: South | F25: Office Supplies | G25: SubCat | H25: Product193 | I25: Cust193 | J25: Home Office | K25: 1865.82 | L25: 2 | M25: 137.66 | N25: 0.14
C26: ORD00103 | D26: 46006 | E26: West | F26: Office Supplies | G26: SubCat | H26: Product103 | I26: Cust103 | J26: Home Office | K26: 1859.37 | L26: 10 | M26: 261.82 | N26: 0.18
C27: ORD00374 | D27: 45951 | E27: South | F27: Office Supplies | G27: SubCat | H27: Product374 | I27: Cust374 | J27: Corporate | K27: 1852.07 | L27: 4 | M27: 656 | N27: 0.21
C28: ORD00297 | D28: 46018 | E28: South | F28: Furniture | G28: SubCat | H28: Product297 | I28: Cust297 | J28: Corporate | K28: 1849.88 | L28: 2 | M28: 599.6 | N28: 0.14
C29: ORD00192 | D29: 45885 | E29: East | F29: Furniture | G29: SubCat | H29: Product192 | I29: Cust192 | J29: Home Office | K29: 1847.85 | L29: 5 | M29: 718.83 | N29: 0.2
C30: ORD00031 | D30: 45698 | E30: East | F30: Technology | G30: SubCat | H30: Product31 | I30: Cust31 | J30: Consumer | K30: 1838.26 | L30: 9 | M30: 96.41 | N30: 0.18
C31: ORD00387 | D31: 45985 | E31: South | F31: Office Supplies | G31: SubCat | H31: Product387 | I31: Cust387 | J31: Home Office | K31: 1838.1 | L31: 2 | M31: 250.96 | N31: 0.22
C32: ORD00309 | D32: 46017 | E32: North | F32: Office Supplies | G32: SubCat | H32: Product309 | I32: Cust309 | J32: Corporate | K32: 1837.03 | L32: 4 | M32: 726.12 | N32: 0.21
C33: ORD00381 | D33: 45812 | E33: North | F33: Office Supplies | G33: SubCat | H33: Product381 | I33: Cust381 | J33: Consumer | K33: 1831.81 | L33: 5 | M33: 615.88 | N33: 0.12
C34: ORD00334 | D34: 45986 | E34: South | F34: Furniture | G34: SubCat | H34: Product334 | I34: Cust334 | J34: Home Office | K34: 1830.95 | L34: 4 | M34: 536.85 | N34: 0.24
A35: 3.Sort& filter which holds above both and | C35: ORD00237 | D35: 45950 | E35: West | F35: Technology | G35: SubCat | H35: Product237 | I35: Cust237 | J35: Consumer | K35: 1821.91 | L35: 5 | M35: 206.47 | N35: 0.26
C36: ORD00058 | D36: 45938 | E36: East | F36: Office Supplies | G36: SubCat | H36: Product58 | I36: Cust58 | J36: Consumer | K36: 1819.14 | L36: 3 | M36: 717.51 | N36: 0.07
C37: ORD00311 | D37: 45888 | E37: East | F37: Technology | G37: SubCat | H37: Product311 | I37: Cust311 | J37: Corporate | K37: 1816.8 | L37: 5 | M37: 522.53 | N37: 0.13
C38: ORD00295 | D38: 45895 | E38: South | F38: Furniture | G38: SubCat | H38: Product295 | I38: Cust295 | J38: Consumer | K38: 1813.17 | L38: 7 | M38: 579.06 | N38: 0.05
C39: ORD00138 | D39: 45940 | E39: North | F39: Technology | G39: SubCat | H39: Product138 | I39: Cust138 | J39: Consumer | K39: 1802.81 | L39: 8 | M39: 147.42 | N39: 0.14
C40: ORD00164 | D40: 45891 | E40: North | F40: Furniture | G40: SubCat | H40: Product164 | I40: Cust164 | J40: Consumer | K40: 1801.25 | L40: 10 | M40: 471.48 | N40: 0.26
C41: ORD00011 | D41: 45778 | E41: East | F41: Furniture | G41: SubCat | H41: Product11 | I41: Cust11 | J41: Consumer | K41: 1797.94 | L41: 10 | M41: 632.53 | N41: 0.21
...

Sheet 05_Conditional_Formatting
A1: Questions | C1: Order_ID | D1: Date | E1: Region | F1: Category | G1: Sub_Category | H1: Product | I1: Customer | J1: Segment | K1: Sales | L1: Quantity | M1: Profit | N1: Discount
A2: 1.Highlight Sales greater than 1000 | C2: ORD00002 | D2: 45954 | E2: West | F2: Technology | G2: SubCat | H2: Product2 | I2: Cust2 | J2: Consumer | K2: 971.62 | L2: 5 | M2: 327.09 | N2: 0.1
A3: 2.Highlight only office Supplies | C3: ORD00003 | D3: 45921 | E3: South | F3: Office Supplies | G3: SubCat | H3: Product3 | I3: Cust3 | J3: Consumer | K3: 182.55 | L3: 8 | M3: 44.65 | N3: 0.08
A4: 3.Apply color scale to Profit between 500 to 1000 | C4: ORD00004 | D4: 45675 | E4: West | F4: Technology | G4: SubCat | H4: Product4 | I4: Cust4 | J4: Consumer | K4: 298.11 | L4: 4 | M4: 109.47 | N4: 0.08
C5: ORD00005 | D5: 45658 | E5: East | F5: Technology | G5: SubCat | H5: Product5 | I5: Cust5 | J5: Consumer | K5: 713.06 | L5: 1 | M5: 186.05 | N5: 0.1
C6: ORD00006 | D6: 45722 | E6: East | F6: Furniture | G6: SubCat | H6: Product6 | I6: Cust6 | J6: Home Office | K6: 1037.92 | L6: 2 | M6: 393.31 | N6: 0.06
C7: ORD00007 | D7: 45975 | E7: East | F7: Technology | G7: SubCat | H7: Product7 | I7: Cust7 | J7: Corporate | K7: 652.03 | L7: 5 | M7: 260.8 | N7: 0.17
C8: ORD00008 | D8: 45692 | E8: North | F8: Furniture | G8: SubCat | H8: Product8 | I8: Cust8 | J8: Consumer | K8: 1260.49 | L8: 2 | M8: 365.39 | N8: 0.07
C9: ORD00009 | D9: 45708 | E9: East | F9: Technology | G9: SubCat | H9: Product9 | I9: Cust9 | J9: Home Office | K9: 1173.22 | L9: 8 | M9: 180.51 | N9: 0.21
C10: ORD00010 | D10: 46005 | E10: North | F10: Office Supplies | G10: SubCat | H10: Product10 | I10: Cust10 | J10: Consumer | K10: 312.23 | L10: 9 | M10: 102.62 | N10: 0.17
C11: ORD00011 | D11: 45778 | E11: East | F11: Furniture | G11: SubCat | H11: Product11 | I11: Cust11 | J11: Consumer | K11: 1797.94 | L11: 10 | M11: 632.53 | N11: 0.21
C12: ORD00012 | D12: 45976 | E12: North | F12: Technology | G12: SubCat | H12: Product12 | I12: Cust12 | J12: Home Office | K12: 1781.4 | L12: 1 | M12: 361.91 | N12: 0.18
C13: ORD00013 | D13: 45928 | E13: South | F13: Furniture | G13: SubCat | H13: Product13 | I13: Cust13 | J13: Home Office | K13: 1205.07 | L13: 9 | M13: 367.14 | N13: 0.1
C14: ORD00014 | D14: 45927 | E14: East | F14: Technology | G14: SubCat | H14: Product14 | I14: Cust14 | J14: Home Office | K14: 913.99 | L14: 1 | M14: 324.67 | N14: 0.12
C15: ORD00015 | D15: 45834 | E15: South | F15: Furniture | G15: SubCat | H15: Product15 | I15: Cust15 | J15: Home Office | K15: 738.88 | L15: 7 | M15: 95.17 | N15: 0.27
C16: ORD00016 | D16: 45986 | E16: East | F16: Office Supplies | G16: SubCat | H16: Product16 | I16: Cust16 | J16: Consumer | K16: 750.85 | L16: 5 | M16: 281.77 | N16: 0.12
... C401: ORD00401 | D401: 45727 | E401: East | F401: Office Supplies | G401: SubCat | H401: Product401 | I401: Cust401 | J401: Home Office | K401: 1638.6 | L401: 6 | M401: 600.12 | N401: 0.07

Sheet 06_Logical_Functions
A1: Questions | B1: Order_ID | C1: Value1 | D1: Value2 | E1: Value3
A2: 1.Classify each record as Profit or Loss | B2: ='01_Main_Dataset'!A2 -> ORD00002 | C2: =IF('01_Main_Dataset'!K2>0,"Profit","Loss") -> Profit | D2: =IF('01_Main_Dataset'!I2>1000,"High","Low") -> Low | E2: ='01_Main_Dataset'!L2 -> 0.1
A3: 2.Categorize Sales into High, Medium, Low | B3: ='01_Main_Dataset'!A3 -> ORD00003 | C3: =IF('01_Main_Dataset'!K3>0,"Profit","Loss") -> Profit | D3: =IF('01_Main_Dataset'!I3>1000,"High","Low") -> Low | E3: ='01_Main_Dataset'!L3 -> 0.08
A4: 3.Flag records with Discount above threshold | B4: ='01_Main_Dataset'!A4 -> ORD00004 | C4: =IF('01_Main_Dataset'!K4>0,"Profit","Loss") -> Profit | D4: =IF('01_Main_Dataset'!I4>1000,"High","Low") -> Low | E4: ='01_Main_Dataset'!L4 -> 0.08
A5: 4.Create nested IF for multi-condition classification | B5: ='01_Main_Dataset'!A5 -> ORD00005 | C5: =IF('01_Main_Dataset'!K5>0,"Profit","Loss") -> Profit | D5: =IF('01_Main_Dataset'!I5>1000,"High","Low") -> Low | E5: ='01_Main_Dataset'!L5 -> 0.1
A6: 5.Generate decision output based on Profit and Sales | B6: ='01_Main_Dataset'!A6 -> ORD00006 | C6: =IF('01_Main_Dataset'!K6>0,"Profit","Loss") -> Profit | D6: =IF('01_Main_Dataset'!I6>1000,"High","Low") -> High | E6: ='01_Main_Dataset'!L6 -> 0.06
B7: ='01_Main_Dataset'!A7 -> ORD00007 | C7: =IF('01_Main_Dataset'!K7>0,"Profit","Loss") -> Profit | D7: =IF('01_Main_Dataset'!I7>1000,"High","Low") -> Low | E7: ='01_Main_Dataset'!L7 -> 0.17
B8: ='01_Main_Dataset'!A8 -> ORD00008 | C8: =IF('01_Main_Dataset'!K8>0,"Profit","Loss") -> Profit | D8: =IF('01_Main_Dataset'!I8>1000,"High","Low") -> High | E8: ='01_Main_Dataset'!L8 -> 0.07
B9: ='01_Main_Dataset'!A9 -> ORD00009 | C9: =IF('01_Main_Dataset'!K9>0,"Profit","Loss") -> Profit | D9: =IF('01_Main_Dataset'!I9>1000,"High","Low") -> High | E9: ='01_Main_Dataset'!L9 -> 0.21
B10: ='01_Main_Dataset'!A10 -> ORD00010 | C10: =IF('01_Main_Dataset'!K10>0,"Profit","Loss") -> Profit | D10: =IF('01_Main_Dataset'!I10>1000,"High","Low") -> Low | E10: ='01_Main_Dataset'!L10 -> 0.17
B11: ='01_Main_Dataset'!A11 -> ORD00011 | C11: =IF('01_Main_Dataset'!K11>0,"Profit","Loss") -> Profit | D11: =IF('01_Main_Dataset'!I11>1000,"High","Low") -> High | E11: ='01_Main_Dataset'!L11 -> 0.21
B12: ='01_Main_Dataset'!A12 -> ORD00012 | C12: =IF('01_Main_Dataset'!K12>0,"Profit","Loss") -> Profit | D12: =IF('01_Main_Dataset'!I12>1000,"High","Low") -> High | E12: ='01_Main_Dataset'!L12 -> 0.18
B13: ='01_Main_Dataset'!A13 -> ORD00013 | C13: =IF('01_Main_Dataset'!K13>0,"Profit","Loss") -> Profit | D13: =IF('01_Main_Dataset'!I13>1000,"High","Low") -> High | E13: ='01_Main_Dataset'!L13 -> 0.1
B14: ='01_Main_Dataset'!A14 -> ORD00014 | C14: =IF('01_Main_Dataset'!K14>0,"Profit","Loss") -> Profit | D14: =IF('01_Main_Dataset'!I14>1000,"High","Low") -> Low | E14: ='01_Main_Dataset'!L14 -> 0.12
B15: ='01_Main_Dataset'!A15 -> ORD00015 | C15: =IF('01_Main_Dataset'!K15>0,"Profit","Loss") -> Profit | D15: =IF('01_Main_Dataset'!I15>1000,"High","Low") -> Low | E15: ='01_Main_Dataset'!L15 -> 0.27
B16: ='01_Main_Dataset'!A16 -> ORD00016 | C16: =IF('01_Main_Dataset'!K16>0,"Profit","Loss") -> Profit | D16: =IF('01_Main_Dataset'!I16>1000,"High","Low") -> Low | E16: ='01_Main_Dataset'!L16 -> 0.12
B17: ='01_Main_Dataset'!A17 -> ORD00017 | C17: =IF('01_Main_Dataset'!K17>0,"Profit","Loss") -> Profit | D17: =IF('01_Main_Dataset'!I17>1000,"High","Low") -> High | E17: ='01_Main_Dataset'!L17 -> 0.25
B18: ='01_Main_Dataset'!A18 -> ORD00018 | C18: =IF('01_Main_Dataset'!K18>0,"Profit","Loss") -> Profit | D18: =IF('01_Main_Dataset'!I18>1000,"High","Low") -> High | E18: ='01_Main_Dataset'!L18 -> 0.28
... B79: ='01_Main_Dataset'!A79 -> ORD00079 | C79: =IF('01_Main_Dataset'!K79>0,"Profit","Loss") -> Profit | D79: =IF('01_Main_Dataset'!I79>1000,"High","Low") -> Low | E79: ='01_Main_Dataset'!L79 -> 0.2

Sheet 07_Advanced_Formulas
A1: Questions | B1: Order_ID | C1: Value1 | D1: Value2 | E1: Value3
A2: 1.Calculate Profit Margin percentage | B2: ='01_Main_Dataset'!A2 -> ORD00002 | C2: =IFERROR('01_Main_Dataset'!K2/'01_Main_Dataset'!I2,0) -> 0.33664396 | D2: ='01_Main_Dataset'!C2 -> West | E2: ='01_Main_Dataset'!I2 -> 971.62
A3: 2.Compute Region-wise Sales using SUMIFS | B3: ='01_Main_Dataset'!A3 -> ORD00003 | C3: =IFERROR('01_Main_Dataset'!K3/'01_Main_Dataset'!I3,0) -> 0.24459052 | D3: ='01_Main_Dataset'!C3 -> South | E3: ='01_Main_Dataset'!I3 -> 182.55
A4: 3.Count orders per Category using COUNTIF | B4: ='01_Main_Dataset'!A4 -> ORD00004 | C4: =IFERROR('01_Main_Dataset'!K4/'01_Main_Dataset'!I4,0) -> 0.36721344 | D4: ='01_Main_Dataset'!C4 -> West | E4: ='01_Main_Dataset'!I4 -> 298.11
A5: 4.Retrieve Product using INDEX-MATCH | B5: ='01_Main_Dataset'!A5 -> ORD00005 | C5: =IFERROR('01_Main_Dataset'!K5/'01_Main_Dataset'!I5,0) -> 0.26091773 | D5: ='01_Main_Dataset'!C5 -> East | E5: ='01_Main_Dataset'!I5 -> 713.06
A6: 5.Calculate average Sales per Segment | B6: ='01_Main_Dataset'!A6 -> ORD00006 | C6: =IFERROR('01_Main_Dataset'!K6/'01_Main_Dataset'!I6,0) -> 0.37894057 | D6: ='01_Main_Dataset'!C6 -> East | E6: ='01_Main_Dataset'!I6 -> 1037.92
B7: ='01_Main_Dataset'!A7 -> ORD00007 | C7: =IFERROR('01_Main_Dataset'!K7/'01_Main_Dataset'!I7,0) -> 0.3999816 | D7: ='01_Main_Dataset'!C7 -> East | E7: ='01_Main_Dataset'!I7 -> 652.03
B8: ='01_Main_Dataset'!A8 -> ORD00008 | C8: =IFERROR('01_Main_Dataset'!K8/'01_Main_Dataset'!I8,0) -> 0.28987933 | D8: ='01_Main_Dataset'!C8 -> North | E8: ='01_Main_Dataset'!I8 -> 1260.49
B9: ='01_Main_Dataset'!A9 -> ORD00009 | C9: =IFERROR('01_Main_Dataset'!K9/'01_Main_Dataset'!I9,0) -> 0.15385861 | D9: ='01_Main_Dataset'!C9 -> East | E9: ='01_Main_Dataset'!I9 -> 1173.22
B10: ='01_Main_Dataset'!A10 -> ORD00010 | C10: =IFERROR('01_Main_Dataset'!K10/'01_Main_Dataset'!I10,0) -> 0.32866797 | D10: ='01_Main_Dataset'!C10 -> North | E10: ='01_Main_Dataset'!I10 -> 312.23
B11: ='01_Main_Dataset'!A11 -> ORD00011 | C11: =IFERROR('01_Main_Dataset'!K11/'01_Main_Dataset'!I11,0) -> 0.35180818 | D11: ='01_Main_Dataset'!C11 -> East | E11: ='01_Main_Dataset'!I11 -> 1797.94
B12: ='01_Main_Dataset'!A12 -> ORD00012 | C12: =IFERROR('01_Main_Dataset'!K12/'01_Main_Dataset'!I12,0) -> 0.20316044 | D12: ='01_Main_Dataset'!C12 -> North | E12: ='01_Main_Dataset'!I12 -> 1781.4
B13: ='01_Main_Dataset'!A13 -> ORD00013 | C13: =IFERROR('01_Main_Dataset'!K13/'01_Main_Dataset'!I13,0) -> 0.3046628 | D13: ='01_Main_Dataset'!C13 -> South | E13: ='01_Main_Dataset'!I13 -> 1205.07
B14: ='01_Main_Dataset'!A14 -> ORD00014 | C14: =IFERROR('01_Main_Dataset'!K14/'01_Main_Dataset'!I14,0) -> 0.3552227 | D14: ='01_Main_Dataset'!C14 -> East | E14: ='01_Main_Dataset'!I14 -> 913.99
B15: ='01_Main_Dataset'!A15 -> ORD00015 | C15: =IFERROR('01_Main_Dataset'!K15/'01_Main_Dataset'!I15,0) -> 0.12880305 | D15: ='01_Main_Dataset'!C15 -> South | E15: ='01_Main_Dataset'!I15 -> 738.88
B16: ='01_Main_Dataset'!A16 -> ORD00016 | C16: =IFERROR('01_Main_Dataset'!K16/'01_Main_Dataset'!I16,0) -> 0.37526803 | D16: ='01_Main_Dataset'!C16 -> East | E16: ='01_Main_Dataset'!I16 -> 750.85
B17: ='01_Main_Dataset'!A17 -> ORD00017 | C17: =IFERROR('01_Main_Dataset'!K17/'01_Main_Dataset'!I17,0) -> 0.29615545 | D17: ='01_Main_Dataset'!C17 -> West | E17: ='01_Main_Dataset'!I17 -> 1196.5
B18: ='01_Main_Dataset'!A18 -> ORD00018 | C18: =IFERROR('01_Main_Dataset'!K18/'01_Main_Dataset'!I18,0) -> 0.13291242 | D18: ='01_Main_Dataset'!C18 -> East | E18: ='01_Main_Dataset'!I18 -> 1042.19
... B79: ='01_Main_Dataset'!A79 -> ORD00079 | C79: =IFERROR('01_Main_Dataset'!K79/'01_Main_Dataset'!I79,0) -> 0.076859405 | D79: ='01_Main_Dataset'!C79 -> South | E79: ='01_Main_Dataset'!I79 -> 918.17

Sheet 08_VLOOKUP
A1: Questions | B1: Order_ID | C1: Sales | D1: Profit
A2: 1.Fetch Sales using Order_ID via VLOOKUP | B2: ='01_Main_Dataset'!A2 -> ORD00002 | C2: =IFERROR(VLOOKUP(B2,'01_Main_Dataset'!A:L,9,FALSE),0) -> 971.62 | D2: =IFERROR(VLOOKUP(B2,'01_Main_Dataset'!A:L,11,FALSE),0) -> 327.09
A3: 2.Fetch Profit using Order_ID via VLOOKUP | B3: ='01_Main_Dataset'!A3 -> ORD00003 | C3: =IFERROR(VLOOKUP(B3,'01_Main_Dataset'!A:L,9,FALSE),0) -> 182.55 | D3: =IFERROR(VLOOKUP(B3,'01_Main_Dataset'!A:L,11,FALSE),0) -> 44.65
A4: 3.Handle missing lookup values with IFERROR | B4: ='01_Main_Dataset'!A4 -> ORD00004 | C4: =IFERROR(VLOOKUP(B4,'01_Main_Dataset'!A:L,9,FALSE),0) -> 298.11 | D4: =IFERROR(VLOOKUP(B4,'01_Main_Dataset'!A:L,11,FALSE),0) -> 109.47
A5: 4.Validate lookup results for accuracy | B5: ='01_Main_Dataset'!A5 -> ORD00005 | C5: =IFERROR(VLOOKUP(B5,'01_Main_Dataset'!A:L,9,FALSE),0) -> 713.06 | D5: =IFERROR(VLOOKUP(B5,'01_Main_Dataset'!A:L,11,FALSE),0) -> 186.05
A6: 5.Compare VLOOKUP results with dataset values | B6: ='01_Main_Dataset'!A6 -> ORD00006 | C6: =IFERROR(VLOOKUP(B6,'01_Main_Dataset'!A:L,9,FALSE),0) -> 1037.92 | D6: =IFERROR(VLOOKUP(B6,'01_Main_Dataset'!A:L,11,FALSE),0) -> 393.31
B7: ='01_Main_Dataset'!A7 -> ORD00007 | C7: =IFERROR(VLOOKUP(B7,'01_Main_Dataset'!A:L,9,FALSE),0) -> 652.03 | D7: =IFERROR(VLOOKUP(B7,'01_Main_Dataset'!A:L,11,FALSE),0) -> 260.8
B8: ='01_Main_Dataset'!A8 -> ORD00008 | C8: =IFERROR(VLOOKUP(B8,'01_Main_Dataset'!A:L,9,FALSE),0) -> 1260.49 | D8: =IFERROR(VLOOKUP(B8,'01_Main_Dataset'!A:L,11,FALSE),0) -> 365.39
B9: ='01_Main_Dataset'!A9 -> ORD00009 | C9: =IFERROR(VLOOKUP(B9,'01_Main_Dataset'!A:L,9,FALSE),0) -> 1173.22 | D9: =IFERROR(VLOOKUP(B9,'01_Main_Dataset'!A:L,11,FALSE),0) -> 180.51
B10: ='01_Main_Dataset'!A10 -> ORD00010 | C10: =IFERROR(VLOOKUP(B10,'01_Main_Dataset'!A:L,9,FALSE),0) -> 312.23 | D10: =IFERROR(VLOOKUP(B10,'01_Main_Dataset'!A:L,11,FALSE),0) -> 102.62
B11: ='01_Main_Dataset'!A11 -> ORD00011 | C11: =IFERROR(VLOOKUP(B11,'01_Main_Dataset'!A:L,9,FALSE),0) -> 1797.94 | D11: =IFERROR(VLOOKUP(B11,'01_Main_Dataset'!A:L,11,FALSE),0) -> 632.53
B12: ='01_Main_Dataset'!A12 -> ORD00012 | C12: =IFERROR(VLOOKUP(B12,'01_Main_Dataset'!A:L,9,FALSE),0) -> 1781.4 | D12: =IFERROR(VLOOKUP(B12,'01_Main_Dataset'!A:L,11,FALSE),0) -> 361.91
B13: ='01_Main_Dataset'!A13 -> ORD00013 | C13: =IFERROR(VLOOKUP(B13,'01_Main_Dataset'!A:L,9,FALSE),0) -> 1205.07 | D13: =IFERROR(VLOOKUP(B13,'01_Main_Dataset'!A:L,11,FALSE),0) -> 367.14
B14: ='01_Main_Dataset'!A14 -> ORD00014 | C14: =IFERROR(VLOOKUP(B14,'01_Main_Dataset'!A:L,9,FALSE),0) -> 913.99 | D14: =IFERROR(VLOOKUP(B14,'01_Main_Dataset'!A:L,11,FALSE),0) -> 324.67
B15: ='01_Main_Dataset'!A15 -> ORD00015 | C15: =IFERROR(VLOOKUP(B15,'01_Main_Dataset'!A:L,9,FALSE),0) -> 738.88 | D15: =IFERROR(VLOOKUP(B15,'01_Main_Dataset'!A:L,11,FALSE),0) -> 95.17
B16: ='01_Main_Dataset'!A16 -> ORD00016 | C16: =IFERROR(VLOOKUP(B16,'01_Main_Dataset'!A:L,9,FALSE),0) -> 750.85 | D16: =IFERROR(VLOOKUP(B16,'01_Main_Dataset'!A:L,11,FALSE),0) -> 281.77
B17: ='01_Main_Dataset'!A17 -> ORD00017 | C17: =IFERROR(VLOOKUP(B17,'01_Main_Dataset'!A:L,9,FALSE),0) -> 1196.5 | D17: =IFERROR(VLOOKUP(B17,'01_Main_Dataset'!A:L,11,FALSE),0) -> 354.35
B18: ='01_Main_Dataset'!A18 -> ORD00018 | C18: =IFERROR(VLOOKUP(B18,'01_Main_Dataset'!A:L,9,FALSE),0) -> 1042.19 | D18: =IFERROR(VLOOKUP(B18,'01_Main_Dataset'!A:L,11,FALSE),0) -> 138.52
... B79: ='01_Main_Dataset'!A79 -> ORD00079 | C79: =IFERROR(VLOOKUP(B79,'01_Main_Dataset'!A:L,9,FALSE),0) -> 918.17 | D79: =IFERROR(VLOOKUP(B79,'01_Main_Dataset'!A:L,11,FALSE),0) -> 70.57

Sheet 09_HLOOKUP
A1: Questions | B1: Sales | C1: Quantity | D1: Profit
A2: 1.Retrieve Sales using HLOOKUP from header row | B2: =HLOOKUP("Sales",'01_Main_Dataset'!A1:L400,2,FALSE) -> 971.62 | C2: =HLOOKUP("Quantity",'01_Main_Dataset'!A1:L400,2,FALSE) -> 5 | D2: =HLOOKUP("Profit",'01_Main_Dataset'!A1:L400,2,FALSE) -> 327.09
A3: 2.Retrieve Quantity using HLOOKUP | B3: =HLOOKUP("Sales",'01_Main_Dataset'!A1:L400,3,FALSE) -> 182.55 | C3: =HLOOKUP("Quantity",'01_Main_Dataset'!A1:L400,3,FALSE) -> 8 | D3: =HLOOKUP("Profit",'01_Main_Dataset'!A1:L400,3,FALSE) -> 44.65
A4: 3.Retrieve Profit using HLOOKUP | B4: =HLOOKUP("Sales",'01_Main_Dataset'!A1:L400,4,FALSE) -> 298.11 | C4: =HLOOKUP("Quantity",'01_Main_Dataset'!A1:L400,4,FALSE) -> 4 | D4: =HLOOKUP("Profit",'01_Main_Dataset'!A1:L400,4,FALSE) -> 109.47
A5: 4.Handle missing values in HLOOKUP using IFERROR | B5: =HLOOKUP("Sales",'01_Main_Dataset'!A1:L400,5,FALSE) -> 713.06 | C5: =HLOOKUP("Quantity",'01_Main_Dataset'!A1:L400,5,FALSE) -> 1 | D5: =HLOOKUP("Profit",'01_Main_Dataset'!A1:L400,5,FALSE) -> 186.05
A6: 5.Validate horizontal lookup accuracy | B6: =HLOOKUP("Sales",'01_Main_Dataset'!A1:L400,6,FALSE) -> 1037.92 | C6: =HLOOKUP("Quantity",'01_Main_Dataset'!A1:L400,6,FALSE) -> 2 | D6: =HLOOKUP("Profit",'01_Main_Dataset'!A1:L400,6,FALSE) -> 393.31
B7: =HLOOKUP("Sales",'01_Main_Dataset'!A1:L400,7,FALSE) -> 652.03 | C7: =HLOOKUP("Quantity",'01_Main_Dataset'!A1:L400,7,FALSE) -> 5 | D7: =HLOOKUP("Profit",'01_Main_Dataset'!A1:L400,7,FALSE) -> 260.8
B8: =HLOOKUP("Sales",'01_Main_Dataset'!A1:L400,8,FALSE) -> 1260.49 | C8: =HLOOKUP("Quantity",'01_Main_Dataset'!A1:L400,8,FALSE) -> 2 | D8: =HLOOKUP("Profit",'01_Main_Dataset'!A1:L400,8,FALSE) -> 365.39
B9: =HLOOKUP("Sales",'01_Main_Dataset'!A1:L400,9,FALSE) -> 1173.22 | C9: =HLOOKUP("Quantity",'01_Main_Dataset'!A1:L400,9,FALSE) -> 8 | D9: =HLOOKUP("Profit",'01_Main_Dataset'!A1:L400,9,FALSE) -> 180.51
B10: =HLOOKUP("Sales",'01_Main_Dataset'!A1:L400,10,FALSE) -> 312.23 | C10: =HLOOKUP("Quantity",'01_Main_Dataset'!A1:L400,10,FALSE) -> 9 | D10: =HLOOKUP("Profit",'01_Main_Dataset'!A1:L400,10,FALSE) -> 102.62
B11: =HLOOKUP("Sales",'01_Main_Dataset'!A1:L400,11,FALSE) -> 1797.94 | C11: =HLOOKUP("Quantity",'01_Main_Dataset'!A1:L400,11,FALSE) -> 10 | D11: =HLOOKUP("Profit",'01_Main_Dataset'!A1:L400,11,FALSE) -> 632.53
B12: =HLOOKUP("Sales",'01_Main_Dataset'!A1:L400,12,FALSE) -> 1781.4 | C12: =HLOOKUP("Quantity",'01_Main_Dataset'!A1:L400,12,FALSE) -> 1 | D12: =HLOOKUP("Profit",'01_Main_Dataset'!A1:L400,12,FALSE) -> 361.91
B13: =HLOOKUP("Sales",'01_Main_Dataset'!A1:L400,13,FALSE) -> 1205.07 | C13: =HLOOKUP("Quantity",'01_Main_Dataset'!A1:L400,13,FALSE) -> 9 | D13: =HLOOKUP("Profit",'01_Main_Dataset'!A1:L400,13,FALSE) -> 367.14
B14: =HLOOKUP("Sales",'01_Main_Dataset'!A1:L400,14,FALSE) -> 913.99 | C14: =HLOOKUP("Quantity",'01_Main_Dataset'!A1:L400,14,FALSE) -> 1 | D14: =HLOOKUP("Profit",'01_Main_Dataset'!A1:L400,14,FALSE) -> 324.67
B15: =HLOOKUP("Sales",'01_Main_Dataset'!A1:L400,15,FALSE) -> 738.88 | C15: =HLOOKUP("Quantity",'01_Main_Dataset'!A1:L400,15,FALSE) -> 7 | D15: =HLOOKUP("Profit",'01_Main_Dataset'!A1:L400,15,FALSE) -> 95.17
B16: =HLOOKUP("Sales",'01_Main_Dataset'!A1:L400,16,FALSE) -> 750.85 | C16: =HLOOKUP("Quantity",'01_Main_Dataset'!A1:L400,16,FALSE) -> 5 | D16: =HLOOKUP("Profit",'01_Main_Dataset'!A1:L400,16,FALSE) -> 281.77
B17: =HLOOKUP("Sales",'01_Main_Dataset'!A1:L400,17,FALSE) -> 1196.5 | C17: =HLOOKUP("Quantity",'01_Main_Dataset'!A1:L400,17,FALSE) -> 2 | D17: =HLOOKUP("Profit",'01_Main_Dataset'!A1:L400,17,FALSE) -> 354.35
B18: =HLOOKUP("Sales",'01_Main_Dataset'!A1:L400,18,FALSE) -> 1042.19 | C18: =HLOOKUP("Quantity",'01_Main_Dataset'!A1:L400,18,FALSE) -> 2 | D18: =HLOOKUP("Profit",'01_Main_Dataset'!A1:L400,18,FALSE) -> 138.52
B19: =HLOOKUP("Sales",'01_Main_Dataset'!A1:L400,19,FALSE) -> 686.09 | C19: =HLOOKUP("Quantity",'01_Main_Dataset'!A1:L400,19,FALSE) -> 6 | D19: =HLOOKUP("Profit",'01_Main_Dataset'!A1:L400,19,FALSE) -> 105.82
B20: =HLOOKUP("Sales",'01_Main_Dataset'!A1:L400,20,FALSE) -> 1416.07 | C20: =HLOOKUP("Quantity",'01_Main_Dataset'!A1:L400,20,FALSE) -> 4 | D20: =HLOOKUP("Profit",'01_Main_Dataset'!A1:L400,20,FALSE) -> 225.85
B21: =HLOOKUP("Sales",'01_Main_Dataset'!A1:L400,21,FALSE) -> 1144.18 | C21: =HLOOKUP("Quantity",'01_Main_Dataset'!A1:L400,21,FALSE) -> 5 | D21: =HLOOKUP("Profit",'01_Main_Dataset'!A1:L400,21,FALSE) -> 233.65
B22: =HLOOKUP("Sales",'01_Main_Dataset'!A1:L400,22,FALSE) -> 252.73 | C22: =HLOOKUP("Quantity",'01_Main_Dataset'!A1:L400,22,FALSE) -> 5 | D22: =HLOOKUP("Profit",'01_Main_Dataset'!A1:L400,22,FALSE) -> 31.14
B23: =HLOOKUP("Sales",'01_Main_Dataset'!A1:L400,23,FALSE) -> 1467.17 | C23: =HLOOKUP("Quantity",'01_Main_Dataset'!A1:L400,23,FALSE) -> 10 | D23: =HLOOKUP("Profit",'01_Main_Dataset'!A1:L400,23,FALSE) -> 157.78
B24: =HLOOKUP("Sales",'01_Main_Dataset'!A1:L400,24,FALSE) -> 939.48 | C24: =HLOOKUP("Quantity",'01_Main_Dataset'!A1:L400,24,FALSE) -> 2 | D24: =HLOOKUP("Profit",'01_Main_Dataset'!A1:L400,24,FALSE) -> 166.13
B25: =HLOOKUP("Sales",'01_Main_Dataset'!A1:L400,25,FALSE) -> 1696.84 | C25: =HLOOKUP("Quantity",'01_Main_Dataset'!A1:L400,25,FALSE) -> 4 | D25: =HLOOKUP("Profit",'01_Main_Dataset'!A1:L400,25,FALSE) -> 348.3
B26: =HLOOKUP("Sales",'01_Main_Dataset'!A1:L400,26,FALSE) -> 788.51 | C26: =HLOOKUP("Quantity",'01_Main_Dataset'!A1:L400,26,FALSE) -> 8 | D26: =HLOOKUP("Profit",'01_Main_Dataset'!A1:L400,26,FALSE) -> 292.33
B27: =HLOOKUP("Sales",'01_Main_Dataset'!A1:L400,27,FALSE) -> 1419.02 | C27: =HLOOKUP("Quantity",'01_Main_Dataset'!A1:L400,27,FALSE) -> 4 | D27: =HLOOKUP("Profit",'01_Main_Dataset'!A1:L400,27,FALSE) -> 500.65
B28: =HLOOKUP("Sales",'01_Main_Dataset'!A1:L400,28,FALSE) -> 159.15 | C28: =HLOOKUP("Quantity",'01_Main_Dataset'!A1:L400,28,FALSE) -> 6 | D28: =HLOOKUP("Profit",'01_Main_Dataset'!A1:L400,28,FALSE) -> 35.23
B29: =HLOOKUP("Sales",'01_Main_Dataset'!A1:L400,29,FALSE) -> 1300.57 | C29: =HLOOKUP("Quantity",'01_Main_Dataset'!A1:L400,29,FALSE) -> 3 | D29: =HLOOKUP("Profit",'01_Main_Dataset'!A1:L400,29,FALSE) -> 416.02
B30: =HLOOKUP("Sales",'01_Main_Dataset'!A1:L400,30,FALSE) -> 491.92 | C30: =HLOOKUP("Quantity",'01_Main_Dataset'!A1:L400,30,FALSE) -> 2 | D30: =HLOOKUP("Profit",'01_Main_Dataset'!A1:L400,30,FALSE) -> 79.93
B31: =HLOOKUP("Sales",'01_Main_Dataset'!A1:L400,31,FALSE) -> 1838.26 | C31: =HLOOKUP("Quantity",'01_Main_Dataset'!A1:L400,31,FALSE) -> 9 | D31: =HLOOKUP("Profit",'01_Main_Dataset'!A1:L400,31,FALSE) -> 96.41
B32: =HLOOKUP("Sales",'01_Main_Dataset'!A1:L400,32,FALSE) -> 194.86 | C32: =HLOOKUP("Quantity",'01_Main_Dataset'!A1:L400,32,FALSE) -> 5 | D32: =HLOOKUP("Profit",'01_Main_Dataset'!A1:L400,32,FALSE) -> 69.54
B33: =HLOOKUP("Sales",'01_Main_Dataset'!A1:L400,33,FALSE) -> 1241.13 | C33: =HLOOKUP("Quantity",'01_Main_Dataset'!A1:L400,33,FALSE) -> 2 | D33: =HLOOKUP("Profit",'01_Main_Dataset'!A1:L400,33,FALSE) -> 151.79
B34: =HLOOKUP("Sales",'01_Main_Dataset'!A1:L400,34,FALSE) -> 1769.91 | C34: =HLOOKUP("Quantity",'01_Main_Dataset'!A1:L400,34,FALSE) -> 10 | D34: =HLOOKUP("Profit",'01_Main_Dataset'!A1:L400,34,FALSE) -> 403.97
B35: =HLOOKUP("Sales",'01_Main_Dataset'!A1:L400,35,FALSE) -> 1881.77 | C35: =HLOOKUP("Quantity",'01_Main_Dataset'!A1:L400,35,FALSE) -> 3 | D35: =HLOOKUP("Profit",'01_Main_Dataset'!A1:L400,35,FALSE) -> 605.05
B36: =HLOOKUP("Sales",'01_Main_Dataset'!A1:L400,36,FALSE) -> 1486.02 | C36: =HLOOKUP("Quantity",'01_Main_Dataset'!A1:L400,36,FALSE) -> 4 | D36: =HLOOKUP("Profit",'01_Main_Dataset'!A1:L400,36,FALSE) -> 470.08
B37: =HLOOKUP("Sales",'01_Main_Dataset'!A1:L400,37,FALSE) -> 192.67 | C37: =HLOOKUP("Quantity",'01_Main_Dataset'!A1:L400,37,FALSE) -> 8 | D37: =HLOOKUP("Profit",'01_Main_Dataset'!A1:L400,37,FALSE) -> 35.73
B38: =HLOOKUP("Sales",'01_Main_Dataset'!A1:L400,38,FALSE) -> 134.3 | C38: =HLOOKUP("Quantity",'01_Main_Dataset'!A1:L400,38,FALSE) -> 7 | D38: =HLOOKUP("Profit",'01_Main_Dataset'!A1:L400,38,FALSE) -> 30.2
B39: =HLOOKUP("Sales",'01_Main_Dataset'!A1:L400,39,FALSE) -> 1758.53 | C39: =HLOOKUP("Quantity",'01_Main_Dataset'!A1:L400,39,FALSE) -> 10 | D39: =HLOOKUP("Profit",'01_Main_Dataset'!A1:L400,39,FALSE) -> 422.09
B40: =HLOOKUP("Sales",'01_Main_Dataset'!A1:L400,40,FALSE) -> 940.78 | C40: =HLOOKUP("Quantity",'01_Main_Dataset'!A1:L400,40,FALSE) -> 5 | D40: =HLOOKUP("Profit",'01_Main_Dataset'!A1:L400,40,FALSE) -> 336.8
...

Sheet Match & Index
A1: Question | H1: Order_ID | I1: Date | J1: Region | K1: Category | L1: Sub_Category | M1: Product | N1: Customer | O1: Segment | P1: Sales | Q1: Quantity | R1: Profit | S1: Discount
A2: 1.Find the order value of serial no 15 | H2: ORD00002 | I2: 45954 | J2: West | K2: Technology | L2: SubCat | M2: Product2 | N2: Cust2 | O2: Consumer | P2: 971.62 | Q2: 5 | R2: 327.09 | S2: 0.1
A3: Using index | B3: function | H3: ORD00003 | I3: 45921 | J3: South | K3: Office Supplies | L3: SubCat | M3: Product3 | N3: Cust3 | O3: Consumer | P3: 182.55 | Q3: 8 | R3: 44.65 | S3: 0.08
A4: sl.no | B4: order value | H4: ORD00004 | I4: 45675 | J4: West | K4: Technology | L4: SubCat | M4: Product4 | N4: Cust4 | O4: Consumer | P4: 298.11 | Q4: 4 | R4: 109.47 | S4: 0.08
A5: 15 | B5: =INDEX(H1:H401,15) -> ORD00015 | H5: ORD00005 | I5: 45658 | J5: East | K5: Technology | L5: SubCat | M5: Product5 | N5: Cust5 | O5: Consumer | P5: 713.06 | Q5: 1 | R5: 186.05 | S5: 0.1
H6: ORD00006 | I6: 45722 | J6: East | K6: Furniture | L6: SubCat | M6: Product6 | N6: Cust6 | O6: Home Office | P6: 1037.92 | Q6: 2 | R6: 393.31 | S6: 0.06
A7: 2. Find the position of Quantity using Match Function | H7: ORD00007 | I7: 45975 | J7: East | K7: Technology | L7: SubCat | M7: Product7 | N7: Cust7 | O7: Corporate | P7: 652.03 | Q7: 5 | R7: 260.8 | S7: 0.17
H8: ORD00008 | I8: 45692 | J8: North | K8: Furniture | L8: SubCat | M8: Product8 | N8: Cust8 | O8: Consumer | P8: 1260.49 | Q8: 2 | R8: 365.39 | S8: 0.07
A9: Value | B9: Position | H9: ORD00009 | I9: 45708 | J9: East | K9: Technology | L9: SubCat | M9: Product9 | N9: Cust9 | O9: Home Office | P9: 1173.22 | Q9: 8 | R9: 180.51 | S9: 0.21
A10: Quantity | B10: =MATCH(A10,H1:S1,0) -> 10 | H10: ORD00010 | I10: 46005 | J10: North | K10: Office Supplies | L10: SubCat | M10: Product10 | N10: Cust10 | O10: Consumer | P10: 312.23 | Q10: 9 | R10: 102.62 | S10: 0.17
H11: ORD00011 | I11: 45778 | J11: East | K11: Furniture | L11: SubCat | M11: Product11 | N11: Cust11 | O11: Consumer | P11: 1797.94 | Q11: 10 | R11: 632.53 | S11: 0.21
H12: ORD00012 | I12: 45976 | J12: North | K12: Technology | L12: SubCat | M12: Product12 | N12: Cust12 | O12: Home Office | P12: 1781.4 | Q12: 1 | R12: 361.91 | S12: 0.18
H13: ORD00013 | I13: 45928 | J13: South | K13: Furniture | L13: SubCat | M13: Product13 | N13: Cust13 | O13: Home Office | P13: 1205.07 | Q13: 9 | R13: 367.14 | S13: 0.1
H14: ORD00014 | I14: 45927 | J14: East | K14: Technology | L14: SubCat | M14: Product14 | N14: Cust14 | O14: Home Office | P14: 913.99 | Q14: 1 | R14: 324.67 | S14: 0.12
H15: ORD00015 | I15: 45834 | J15: South | K15: Furniture | L15: SubCat | M15: Product15 | N15: Cust15 | O15: Home Office | P15: 738.88 | Q15: 7 | R15: 95.17 | S15: 0.27
H16: ORD00016 | I16: 45986 | J16: East | K16: Office Supplies | L16: SubCat | M16: Product16 | N16: Cust16 | O16: Consumer | P16: 750.85 | Q16: 5 | R16: 281.77 | S16: 0.12
H17: ORD00017 | I17: 45884 | J17: West | K17: Office Supplies | L17: SubCat | M17: Product17 | N17: Cust17 | O17: Home Office | P17: 1196.5 | Q17: 2 | R17: 354.35 | S17: 0.25
H18: ORD00018 | I18: 45771 | J18: East | K18: Office Supplies | L18: SubCat | M18: Product18 | N18: Cust18 | O18: Home Office | P18: 1042.19 | Q18: 2 | R18: 138.52 | S18: 0.28
H19: ORD00019 | I19: 45716 | J19: North | K19: Furniture | L19: SubCat | M19: Product19 | N19: Cust19 | O19: Home Office | P19: 686.09 | Q19: 6 | R19: 105.82 | S19: 0.13
H20: ORD00020 | I20: 45989 | J20: East | K20: Office Supplies | L20: SubCat | M20: Product20 | N20: Cust20 | O20: Corporate | P20: 1416.07 | Q20: 4 | R20: 225.85 | S20: 0.17
H21: ORD00021 | I21: 45928 | J21: North | K21: Technology | L21: SubCat | M21: Product21 | N21: Cust21 | O21: Home Office | P21: 1144.18 | Q21: 5 | R21: 233.65 | S21: 0.11
H22: ORD00022 | I22: 45878 | J22: North | K22: Technology | L22: SubCat | M22: Product22 | N22: Cust22 | O22: Home Office | P22: 252.73 | Q22: 5 | R22: 31.14 | S22: 0.27
... H401: ORD00401 | I401: 45727 | J401: East | K401: Office Supplies | L401: SubCat | M401: Product401 | N401: Cust401 | O401: Home Office | P401: 1638.6 | Q401: 6 | R401: 600.12 | S401: 0.07

Sheet 10_Pivot_Tables
A1: Questions | B1: Category | C1: Region | D1: Sum of Sales | E1: Sum of Profit
A2: 1.Summarize total Sales by Region | B2: Furniture | C2: East | D2: 46152.74 | E2: 11866.02
A3: 2.Analyze Profit by Category | B3: Furniture | C3: North | D3: 23614.86 | E3: 5252.16
A4: 3.Repeat all category in each region | B4: Furniture | C4: South | D4: 42193.72 | E4: 9397.3
A5: 4. Use blanks Rows after each category | B5: Furniture | C5: West | D5: 22211.11 | E5: 5228.81
B6: Furniture Total | D6: 134172.43 | E6: 31744.29
B7: Office Supplies | C7: East | D7: 39127 | E7: 9409.6
B8: Office Supplies | C8: North | D8: 23251.82 | E8: 5561.7
B9: Office Supplies | C9: South | D9: 42595.05 | E9: 9714.61
B10: Office Supplies | C10: West | D10: 50906.97 | E10: 10780.2
B11: Office Supplies Total | D11: 155880.84 | E11: 35466.11
B12: Technology | C12: East | D12: 42482.64 | E12: 9104.72
B13: Technology | C13: North | D13: 28487.28 | E13: 7138.49
B14: Technology | C14: South | D14: 30677.43 | E14: 6418
B15: Technology | C15: West | D15: 31511.18 | E15: 7026.05
B16: Technology Total | D16: 133158.53 | E16: 29687.26
B17: Grand Total | D17: 423211.8 | E17: 96897.66

Sheet Sheet3
A3: Row Labels | B3: Count of Product
A4: Furniture | B4: 129
A5: Office Supplies | B5: 136
A6: Technology | B6: 135

Sheet Sheet5
A3: Row Labels | B3: Sum of Sales
A4: Jan | B4: 34152.6
A5: Feb | B5: 30597.51
A6: Mar | B6: 48695.15
A7: Apr | B7: 29491.2
A8: May | B8: 35527.06
A9: Jun | B9: 33791.8
A10: Jul | B10: 31030.49
A11: Aug | B11: 34995.1
A12: Sep | B12: 25192.01
A13: Oct | B13: 42099.7
A14: Nov | B14: 33042.58
A15: Dec | B15: 42036.2

Sheet Sheet6
A3: Row Labels | B3: Sum of Discount
A4: Consumer | B4: 19.2
A5: Corporate | B5: 16.92
A6: Home Office | B6: 23.28

Sheet Dashboard
F1: Sales & Performance Analysis Dashboard
