Workbook

Sheet Product Sheet -VLOOKUP
A1: Worksheet 1: Products
A3: ProductID | B3: Product | C3: Price
A4: 101 | B4: Product A | C4: 120
A5: 102 | B5: Product B | C5: 150
A6: 103 | B6: Product C | C6: 200
A7: 104 | B7: Product D | C7: 90
A8: 105 | B8: Product E | C8: 220
A9: 106 | B9: Product F | C9: 130

Sheet Order Sheet-VLOOKUP
A1: Worksheet 2: Orders
A3: OrderID | B3: ProductID | C3: Quantity | D3: TotalPrice | F3: Name:- Debkanta Nandi
A4: 1 | B4: 101 | C4: 2 | G4: DPBA,ANP-D3870
A5: 2 | B5: 103 | C5: 1
A6: 3 | B6: 105 | C6: 4
A7: 4 | B7: 106 | C7: 3
A8: 5 | B8: 102 | C8: 5
A9: 6 | B9: 104 | C9: 6
A12: 1. Use VLOOKUP to find the product names for each ProductID in the Orders worksheet.
A14: OrderID | B14: ProductID | C14: Product Name
A15: 1 | B15: 101 | C15: =VLOOKUP($B15,'Product Sheet -VLOOKUP'!$A$3:$C$9,2,FALSE) -> Product A
A16: 2 | B16: 103 | C16: =VLOOKUP($B16,'Product Sheet -VLOOKUP'!$A$3:$C$9,2,FALSE) -> Product C
A17: 3 | B17: 105 | C17: =VLOOKUP($B17,'Product Sheet -VLOOKUP'!$A$3:$C$9,2,FALSE) -> Product E
A18: 4 | B18: 106 | C18: =VLOOKUP($B18,'Product Sheet -VLOOKUP'!$A$3:$C$9,2,FALSE) -> Product F
A19: 5 | B19: 102 | C19: =VLOOKUP($B19,'Product Sheet -VLOOKUP'!$A$3:$C$9,2,FALSE) -> Product B
A20: 6 | B20: 104 | C20: =VLOOKUP($B20,'Product Sheet -VLOOKUP'!$A$3:$C$9,2,FALSE) -> Product D
A22: 2. Use VLOOKUP to find the price for each ProductID in the Orders worksheet, then calculate the TotalPrice by multiplying the Quantity by the Product Price
A24: OrderID | B24: ProductID | C24: Quantity | D24: Product Name | E24: Price | F24: Total Price
A25: 1 | B25: 101 | C25: 2 | D25: =VLOOKUP($B25,'Product Sheet -VLOOKUP'!$A$3:$C$9,2,FALSE) -> Product A | E25: =VLOOKUP($B25,'Product Sheet -VLOOKUP'!$A$3:$C$9,3,FALSE) -> 120 | F25: =$C25*$E25 -> 240
A26: 2 | B26: 103 | C26: 1 | D26: =VLOOKUP($B26,'Product Sheet -VLOOKUP'!$A$3:$C$9,2,FALSE) -> Product C | E26: =VLOOKUP($B26,'Product Sheet -VLOOKUP'!$A$3:$C$9,3,FALSE) -> 200 | F26: =$C26*$E26 -> 200
A27: 3 | B27: 105 | C27: 4 | D27: =VLOOKUP($B27,'Product Sheet -VLOOKUP'!$A$3:$C$9,2,FALSE) -> Product E | E27: =VLOOKUP($B27,'Product Sheet -VLOOKUP'!$A$3:$C$9,3,FALSE) -> 220 | F27: =$C27*$E27 -> 880
A28: 4 | B28: 106 | C28: 3 | D28: =VLOOKUP($B28,'Product Sheet -VLOOKUP'!$A$3:$C$9,2,FALSE) -> Product F | E28: =VLOOKUP($B28,'Product Sheet -VLOOKUP'!$A$3:$C$9,3,FALSE) -> 130 | F28: =$C28*$E28 -> 390
A29: 5 | B29: 102 | C29: 5 | D29: =VLOOKUP($B29,'Product Sheet -VLOOKUP'!$A$3:$C$9,2,FALSE) -> Product B | E29: =VLOOKUP($B29,'Product Sheet -VLOOKUP'!$A$3:$C$9,3,FALSE) -> 150 | F29: =$C29*$E29 -> 750
A30: 6 | B30: 104 | C30: 6 | D30: =VLOOKUP($B30,'Product Sheet -VLOOKUP'!$A$3:$C$9,2,FALSE) -> Product D | E30: =VLOOKUP($B30,'Product Sheet -VLOOKUP'!$A$3:$C$9,3,FALSE) -> 90 | F30: =$C30*$E30 -> 540
A32: 3. Use VLOOKUP to check if there are any ProductIDs in the Orders worksheet that do not exist in the Products worksheet
B34: ProductID | C34: Results
B35: 101 | C35: =IF(ISNA(VLOOKUP($B35,'Product Sheet -VLOOKUP'!$A$3:$C$9,1,FALSE)),"Not Exit","Exit") -> Exit
B36: 103 | C36: =IF(ISNA(VLOOKUP($B36,'Product Sheet -VLOOKUP'!$A$3:$C$9,1,FALSE)),"Not Exit","Exit") -> Exit
B37: 105 | C37: =IF(ISNA(VLOOKUP($B37,'Product Sheet -VLOOKUP'!$A$3:$C$9,1,FALSE)),"Not Exit","Exit") -> Exit
B38: 106 | C38: =IF(ISNA(VLOOKUP($B38,'Product Sheet -VLOOKUP'!$A$3:$C$9,1,FALSE)),"Not Exit","Exit") -> Exit
B39: 102 | C39: =IF(ISNA(VLOOKUP($B39,'Product Sheet -VLOOKUP'!$A$3:$C$9,1,FALSE)),"Not Exit","Exit") -> Exit
B40: 104 | C40: =IF(ISNA(VLOOKUP($B40,'Product Sheet -VLOOKUP'!$A$3:$C$9,1,FALSE)),"Not Exit","Exit") -> Exit
A42: 4. Assume a discount of 10% is given on all products. Use VLOOKUP to find the original price and then calculate the discounted price.
A44: OrderID | B44: ProductID | C44: Quantity | D44: Product Name | E44: Price | F44: Discount(10%) | G44: Discounted Price
A45: 1 | B45: 101 | C45: 2 | D45: =VLOOKUP($B45,'Product Sheet -VLOOKUP'!$A$3:$C$9,2,FALSE) -> Product A | E45: =VLOOKUP($B45,'Product Sheet -VLOOKUP'!$A$3:$C$9,3,FALSE) -> 120 | F45: =E45*10% -> 12 | G45: =E45-F45 -> 108
A46: 2 | B46: 103 | C46: 1 | D46: =VLOOKUP($B46,'Product Sheet -VLOOKUP'!$A$3:$C$9,2,FALSE) -> Product C | E46: =VLOOKUP($B46,'Product Sheet -VLOOKUP'!$A$3:$C$9,3,FALSE) -> 200 | F46: =E46*10% -> 20 | G46: =E46-F46 -> 180
A47: 3 | B47: 105 | C47: 4 | D47: =VLOOKUP($B47,'Product Sheet -VLOOKUP'!$A$3:$C$9,2,FALSE) -> Product E | E47: =VLOOKUP($B47,'Product Sheet -VLOOKUP'!$A$3:$C$9,3,FALSE) -> 220 | F47: =E47*10% -> 22 | G47: =E47-F47 -> 198
A48: 4 | B48: 106 | C48: 3 | D48: =VLOOKUP($B48,'Product Sheet -VLOOKUP'!$A$3:$C$9,2,FALSE) -> Product F | E48: =VLOOKUP($B48,'Product Sheet -VLOOKUP'!$A$3:$C$9,3,FALSE) -> 130 | F48: =E48*10% -> 13 | G48: =E48-F48 -> 117
A49: 5 | B49: 102 | C49: 5 | D49: =VLOOKUP($B49,'Product Sheet -VLOOKUP'!$A$3:$C$9,2,FALSE) -> Product B | E49: =VLOOKUP($B49,'Product Sheet -VLOOKUP'!$A$3:$C$9,3,FALSE) -> 150 | F49: =E49*10% -> 15 | G49: =E49-F49 -> 135
A50: 6 | B50: 104 | C50: 6 | D50: =VLOOKUP($B50,'Product Sheet -VLOOKUP'!$A$3:$C$9,2,FALSE) -> Product D | E50: =VLOOKUP($B50,'Product Sheet -VLOOKUP'!$A$3:$C$9,3,FALSE) -> 90 | F50: =E50*10% -> 9 | G50: =E50-F50 -> 81
...
